Please enter your phone (or bot token): Traceback (most recent call last):
  File "/home/ok_no/telegram_sender-msgs/main.py", line 409, in <module>
    with client:
  File "/home/ok_no/telegram_sender-msgs/env/lib/python3.11/site-packages/telethon/helpers.py", line 219, in _sync_enter
    return loop.run_until_complete(self.__aenter__())
           ^^^^^^^^^^^^^^^^^^^^^^^^^^^^^^^^^^^^^^^^^^
  File "/usr/lib/python3.11/asyncio/base_events.py", line 653, in run_until_complete
    return future.result()
           ^^^^^^^^^^^^^^^
  File "/home/ok_no/telegram_sender-msgs/env/lib/python3.11/site-packages/telethon/client/auth.py", line 657, in __aenter__
    return await self.start()
           ^^^^^^^^^^^^^^^^^^
  File "/home/ok_no/telegram_sender-msgs/env/lib/python3.11/site-packages/telethon/client/auth.py", line 165, in _start
    value = phone()
            ^^^^^^^
  File "/home/ok_no/telegram_sender-msgs/env/lib/python3.11/site-packages/telethon/client/auth.py", line 22, in <lambda>
    phone: typing.Callable[[], str] = lambda: input('Please enter your phone (or bot token): '),
                                              ^^^^^^^^^^^^^^^^^^^^^^^^^^^^^^^^^^^^^^^^^^^^^^^^^
OSError: [Errno 9] Bad file descriptor
./run.sh: рядок 13: 151525 Помилка адресування             (збережено знімок оперативної пам’яті)python3 main.py anon3.session
